Workbook

Sheet PRINCIPAL
A1: Subclasse CNAE 2.0 | B1: Denominação | C1: IN 003 visa Alto Risco | D1: IN visa 003 Médio Risco | E1: IN visa 003 Baixo Risco | F1: IMA BAIXO RISCO
A2: 0111-3/01 | B2: Cultivo de arroz | C2: =IF(COUNTIF('IN 003 VISA'!G:G,A2)>0,"SIM","NÃO") -> NÃO | D2: =IF(COUNTIF('IN 003 VISA'!D:D,A2)>0,"SIM","NÃO") -> NÃO | E2: =IF(COUNTIF('IN 003 VISA'!A:A,A2)>0,"SIM","NÃO") -> SIM | F2: =IF(COUNTIF('Lista IMA'!A:A,A2)>0,"SIM","NÃO") -> NÃO
A3: 0111-3/02 | B3: Cultivo de milho | C3: =IF(COUNTIF('IN 003 VISA'!G:G,A3)>0,"SIM","NÃO") -> NÃO | D3: =IF(COUNTIF('IN 003 VISA'!D:D,A3)>0,"SIM","NÃO") -> NÃO | E3: =IF(COUNTIF('IN 003 VISA'!A:A,A3)>0,"SIM","NÃO") -> SIM | F3: =IF(COUNTIF('Lista IMA'!A:A,A3)>0,"SIM","NÃO") -> SIM
A4: 0111-3/03 | B4: Cultivo de trigo | C4: =IF(COUNTIF('IN 003 VISA'!G:G,A4)>0,"SIM","NÃO") -> NÃO | D4: =IF(COUNTIF('IN 003 VISA'!D:D,A4)>0,"SIM","NÃO") -> NÃO | E4: =IF(COUNTIF('IN 003 VISA'!A:A,A4)>0,"SIM","NÃO") -> SIM | F4: =IF(COUNTIF('Lista IMA'!A:A,A4)>0,"SIM","NÃO") -> SIM
A5: 0111-3/99 | B5: Cultivo de outros cereais não especificados anteriormente | C5: =IF(COUNTIF('IN 003 VISA'!G:G,A5)>0,"SIM","NÃO") -> NÃO | D5: =IF(COUNTIF('IN 003 VISA'!D:D,A5)>0,"SIM","NÃO") -> NÃO | E5: =IF(COUNTIF('IN 003 VISA'!A:A,A5)>0,"SIM","NÃO") -> SIM | F5: =IF(COUNTIF('Lista IMA'!A:A,A5)>0,"SIM","NÃO") -> SIM
A6: 0112-1/01 | B6: Cultivo de algodão herbáceo | C6: =IF(COUNTIF('IN 003 VISA'!G:G,A6)>0,"SIM","NÃO") -> NÃO | D6: =IF(COUNTIF('IN 003 VISA'!D:D,A6)>0,"SIM","NÃO") -> NÃO | E6: =IF(COUNTIF('IN 003 VISA'!A:A,A6)>0,"SIM","NÃO") -> SIM | F6: =IF(COUNTIF('Lista IMA'!A:A,A6)>0,"SIM","NÃO") -> SIM
A7: 0112-1/02 | B7: Cultivo de juta | C7: =IF(COUNTIF('IN 003 VISA'!G:G,A7)>0,"SIM","NÃO") -> NÃO | D7: =IF(COUNTIF('IN 003 VISA'!D:D,A7)>0,"SIM","NÃO") -> NÃO | E7: =IF(COUNTIF('IN 003 VISA'!A:A,A7)>0,"SIM","NÃO") -> SIM | F7: =IF(COUNTIF('Lista IMA'!A:A,A7)>0,"SIM","NÃO") -> SIM
A8: 0112-1/99 | B8: Cultivo de outras fibras de lavoura temporária não especificadas anteriormente | C8: =IF(COUNTIF('IN 003 VISA'!G:G,A8)>0,"SIM","NÃO") -> NÃO | D8: =IF(COUNTIF('IN 003 VISA'!D:D,A8)>0,"SIM","NÃO") -> NÃO | E8: =IF(COUNTIF('IN 003 VISA'!A:A,A8)>0,"SIM","NÃO") -> SIM | F8: =IF(COUNTIF('Lista IMA'!A:A,A8)>0,"SIM","NÃO") -> SIM
A9: 0113-0/00 | B9: Cultivo de cana-de-açúcar | C9: =IF(COUNTIF('IN 003 VISA'!G:G,A9)>0,"SIM","NÃO") -> NÃO | D9: =IF(COUNTIF('IN 003 VISA'!D:D,A9)>0,"SIM","NÃO") -> NÃO | E9: =IF(COUNTIF('IN 003 VISA'!A:A,A9)>0,"SIM","NÃO") -> SIM | F9: =IF(COUNTIF('Lista IMA'!A:A,A9)>0,"SIM","NÃO") -> SIM
A10: 0114-8/00 | B10: Cultivo de fumo | C10: =IF(COUNTIF('IN 003 VISA'!G:G,A10)>0,"SIM","NÃO") -> NÃO | D10: =IF(COUNTIF('IN 003 VISA'!D:D,A10)>0,"SIM","NÃO") -> NÃO | E10: =IF(COUNTIF('IN 003 VISA'!A:A,A10)>0,"SIM","NÃO") -> SIM | F10: =IF(COUNTIF('Lista IMA'!A:A,A10)>0,"SIM","NÃO") -> SIM
A11: 0115-6/00 | B11: Cultivo de soja | C11: =IF(COUNTIF('IN 003 VISA'!G:G,A11)>0,"SIM","NÃO") -> NÃO | D11: =IF(COUNTIF('IN 003 VISA'!D:D,A11)>0,"SIM","NÃO") -> NÃO | E11: =IF(COUNTIF('IN 003 VISA'!A:A,A11)>0,"SIM","NÃO") -> SIM | F11: =IF(COUNTIF('Lista IMA'!A:A,A11)>0,"SIM","NÃO") -> SIM
A12: 0116-4/01 | B12: Cultivo de amendoim | C12: =IF(COUNTIF('IN 003 VISA'!G:G,A12)>0,"SIM","NÃO") -> NÃO | D12: =IF(COUNTIF('IN 003 VISA'!D:D,A12)>0,"SIM","NÃO") -> NÃO | E12: =IF(COUNTIF('IN 003 VISA'!A:A,A12)>0,"SIM","NÃO") -> SIM | F12: =IF(COUNTIF('Lista IMA'!A:A,A12)>0,"SIM","NÃO") -> SIM
A13: 0116-4/02 | B13: Cultivo de girassol | C13: =IF(COUNTIF('IN 003 VISA'!G:G,A13)>0,"SIM","NÃO") -> NÃO | D13: =IF(COUNTIF('IN 003 VISA'!D:D,A13)>0,"SIM","NÃO") -> NÃO | E13: =IF(COUNTIF('IN 003 VISA'!A:A,A13)>0,"SIM","NÃO") -> SIM | F13: =IF(COUNTIF('Lista IMA'!A:A,A13)>0,"SIM","NÃO") -> SIM
... A1338: 9900-8/00 | B1338: Organismos internacionais e outras instituições extraterritoriais | C1338: =IF(COUNTIF('IN 003 VISA'!G:G,A1338)>0,"SIM","NÃO") -> NÃO | D1338: =IF(COUNTIF('IN 003 VISA'!D:D,A1338)>0,"SIM","NÃO") -> NÃO | E1338: =IF(COUNTIF('IN 003 VISA'!A:A,A1338)>0,"SIM","NÃO") -> SIM | F1338: =IF(COUNTIF('Lista IMA'!A:A,A1338)>0,"SIM","NÃO") -> SIM

Sheet Lei Estadual 18091-21
A1: Nº | B1: Atividade Econômica
A2: 1 | B2: Agenciamento de espaços para publicidade, exceto em veículos de comunicação (Código CNAE:7312200) | C2: 7312-2/00
A3: 2 | B3: Agenciamento de profissionais para atividades esportivas, culturais e artísticas (Código CNAE:7490105) | C3: 7490-1/05
A4: 3 | B4: Agências de notícias (Código CNAE:6391700) | C4: 6391-7/00
A5: 4 | B5: Agências de publicidade (Código CNAE:7311400) | C5: 7311-4/00
A6: 5 | B6: Agências de viagens (Código CNAE:7911200) | C6: 7911-2/00
A7: 6 | B7: Agências matrimoniais (Código CNAE:9609202) | C7: 9609-2/02
A8: 7 | B8: Albergues, exceto assistenciais (Código CNAE:5590601) | C8: 5590-6/01
A9: 8 | B9: Aluguel de aparelhos de jogos eletrônicos (Código CNAE:7729201) | C9: 7729-2/01
A10: 9 | B10: Aluguel de equipamentos recreativos e esportivos (Código CNAE:7721700) | C10: 7721-7/00
A11: 10 | B11: Aluguel de fitas de vídeo, DVDs e similares (Código CNAE:7722500) | C11: 7722-5/00
A12: 11 | B12: Aluguel de imóveis próprios (Código CNAE:6810202) | C12: 6810-2/02
A13: 12 | B13: Aluguel de máquinas e equipamentos para escritório (Código CNAE:7733100) | C13: 7733-1/00
... A291: 290 | B291: Web design (Código CNAE:6201502) | C291: 6201-5/02

Sheet Res 51 e 59
A1: Código CNAE | B1: Descrição da atividade econômica | C1: Condição para classificação em baixo risco, "baixo risco A", risco leve, irrelevante ou inexistente
A2: 0121-1/01 | B2: Horticultura, exceto morango
A3: 1031-7/00 | B3: Fabricação de conservas de frutas | C3: Desde que o resultado do exercício da atividade econômica não seja diferente de produto artesanal
A4: 1032-5/99 | B4: Fabricação de conservas de legumes e outros vegetais, exceto palmito | C4: Desde que o resultado do exercício da atividade econômica não seja diferente de produto artesanal
A5: 1033-3/02 | B5: Fabricação de sucos de frutas, hortaliças e legumes, exceto concentrados
A6: 1091-1/02 | B6: Fabricação de produtos de padaria e confeitaria com predominância de produção própria
A7: 1092-9/00 | B7: Fabricação de biscoitos e bolachas | C7: Desde que o resultado do exercício da atividade econômica não seja diferente de produto artesanal
A8: 1093-7/01 | B8: Fabricação de produtos derivados do cacau e de chocolates | C8: Desde que o resultado do exercício da atividade econômica não seja diferente de produto artesanal
A9: 1093-7/02 | B9: Fabricação de frutas cristalizadas, balas e semelhantes | C9: Desde que o resultado do exercício da atividade econômica não seja diferente de produto artesanal
A10: 1094-5/00 | B10: Fabricação de massas alimentícias | C10: Desde que o resultado do exercício da atividade econômica não seja diferente de produto artesanal
A11: 1095-3/00 | B11: Fabricação de especiarias, molhos, temperos e condimentos | C11: Desde que o resultado do exercício da atividade econômica não seja diferente de especiaria ou condimento desidratado produzido artesanalmente
A12: 1096-1/00 | B12: Fabricação de alimentos e pratos prontos | C12: Desde que o resultado do exercício da atividade econômica não seja diferente de produto artesanal
A13: 1099-6/04 | B13: Fabricação de gelo comum | C13: Desde que o gelo fabricado não seja para consumo humano e não entrará em contato com alimentos e bebidas
A14: 1311-1/00 | B14: Preparação e fiação de fibras de algodão
A15: 1312-0/00 | B15: Preparação e fiação de fibras têxteis naturais, exceto algodão
A16: 1340-5/99 | B16: Outros serviços de acabamento em fios, tecidos, artefatos têxteis e peças do vestuário
A17: 1351-1/00 | B17: Fabricação de artefatos têxteis para uso doméstico
A18: 1354-5/00 | B18: Fabricação de tecidos especiais, inclusive artefatos
A19: 1359-6/00 | B19: Fabricação de outros produtos têxteis não especificados anteriormente
A20: 1411-8/01 | B20: Confecção de roupas íntimas
A21: 1411-8/02 | B21: Facção de roupas íntimas
A22: 1412-6/01 | B22: Confecção de peças do vestuário, exceto roupas íntimas e as confeccionadas sob medida
A23: 1412-6/02 | B23: Confecção, sob medida, de peças do vestuário, exceto roupas íntimas
A24: 1412-6/03 | B24: Facção de peças do vestuário, exceto roupas íntimas
A25: 1413-4/01 | B25: Confecção de roupas profissionais, exceto sob medida
... A35: 1822-9/99 | B35: Serviços de acabamentos gráficos, exceto encadernação e plastificação
A36: 2319-2/00 | B36: Fabricação de artigos de vidro | C36: Desde que o resultado do exercício da atividade econômica não seja um produto industrial, não haja operações de espelhação e não haja produção de peças de fibra de vidro
A37: 2399-1/01 | B37: Decoração, lapidação, gravação, vitrificação e outros trabalhos em cerâmica, louça, vidro e cristal
A38: 2539-0/01 | B38: Serviços de usinagem, tornearia e solda | C38: Desde que não haja operações de jateamento (jato de areia)
A39: 3250-7/06 | B39: Serviços de prótese dentária
A40: 3250-7/07 | B40: Fabricação de artigos ópticos | C40: Desde que não haja fabricação de produto para saúde
A41: 3291-4/00 | B41: Fabricação de escovas, pincéis e vassouras | C41: Desde que não haja no exercício a fabricação de escova dental
A42: 3299-0/02 | B42: Fabricação de canetas, lápis e outros artigos para escritório | C42: Desde que não haja armazenamento e/ou geração de resíduos químicos perigosos
A43: 3299-0/06 | B43: Fabricação de velas, inclusive decorativas | C43: Desde que não haja no exercício da atividade a fabricação de velas, sebo e/ou estearina utilizadas como cosmético ou saneante
A44: 3312-1/02 | B44: Manutenção e reparação de aparelhos e instrumentos de medida, teste e controle
A45: 3312-1/04 | B45: Manutenção e reparação de equipamentos e instrumentos ópticos
A46: 3313-9/02 | B46: Manutenção e reparação de baterias e acumuladores elétricos, exceto para veículos
A47: 3314-7/01 | B47: Manutenção e reparação de máquinas motrizes Não- elétricas
A48: 3314-7/02 | B48: Manutenção e reparação de equipamentos hidráulicos e pneumáticos, exceto válvulas
A49: 3314-7/03 | B49: Manutenção e reparação de válvulas industriais
...

Sheet IN 003 VISA
B1: BAIXO RISCO (ANEXO I) | E1: MÉDIO RISCO (ANEXO II) | H1: ALTO RISCO (ANEXO III)
A2: Cód CNAE | B2: Denominação | D2: Cód CNAE | E2: Denominação | G2: Cód CNAE | H2: Denominação
A3: 0111-3/01 | B3: Cultivo de arroz | C3: =MATCH(A3,PRINCIPAL!A:A,0) -> 2 | D3: 1031-7/00 | E3: Fabricação de conservas de frutas | G3: 0892-4/03 | H3: Refino e outros tratamentos do sal
A4: 0111-3/02 | B4: Cultivo de milho | C4: =MATCH(A4,PRINCIPAL!A:A,0) -> 3 | D4: 1032-5/99 | E4: Fabricação de conservas de legumes e outros vegetais, exceto palmito | G4: 1032-5/01 | H4: Fabricação de conservas de palmito
A5: 0111-3/03 | B5: Cultivo de trigo | C5: =MATCH(A5,PRINCIPAL!A:A,0) -> 4 | D5: 1063-5/00 | E5: Fabricação de farinha de mandioca e derivados | G5: 1042-2/00 | H5: Fabricação de óleos vegetais refinados, exceto óleo de milho
A6: 0111-3/99 | B6: Cultivo de outros cereais não especificados anteriormente | C6: =MATCH(A6,PRINCIPAL!A:A,0) -> 5 | D6: 1064-3/00 | E6: Fabricação de farinha de milho e derivados, exceto óleos de milho | G6: 1053-8/00 | H6: Fabricação de sorvetes e outros gelados comestíveis
A7: 0112-1/01 | B7: Cultivo de algodão herbáceo | C7: =MATCH(A7,PRINCIPAL!A:A,0) -> 6 | D7: 1065-1/01 | E7: Fabricação de amidos e féculas de vegetais | G7: 1061-9/01 | H7: Beneficiamento de arroz
A8: 0112-1/02 | B8: Cultivo de juta | C8: =MATCH(A8,PRINCIPAL!A:A,0) -> 7 | D8: 1069-4/00 | E8: Moagem e fabricação de produtos de origem vegetal não especificados anteriormente | G8: 1061-9/02 | H8: Fabricação de produtos do arroz
A9: 0112-1/99 | B9: Cultivo de outras fibras de lavoura temporária não especificadas anteriormente | C9: =MATCH(A9,PRINCIPAL!A:A,0) -> 8 | D9: 1071-6/00 | E9: Fabricação de açúcar em bruto | G9: 1062-7/00 | H9: Moagem de trigo e fabricação de derivados
A10: 0113-0/00 | B10: Cultivo de cana-de-açúcar | C10: =MATCH(A10,PRINCIPAL!A:A,0) -> 9 | D10: 1072-4/01 | E10: Fabricação de açúcar de cana refinado | G10: 1065-1/03 | H10: Fabricação de óleo de milho refinado
A11: 0114-8/00 | B11: Cultivo de fumo | C11: =MATCH(A11,PRINCIPAL!A:A,0) -> 10 | D11: 1072-4/02 | E11: Fabricação de açúcar de cereais (dextrose) e de beterraba | G11: 1081-3/01 | H11: Beneficiamento de café
A12: 0115-6/00 | B12: Cultivo de soja | C12: =MATCH(A12,PRINCIPAL!A:A,0) -> 11 | D12: 1096-1/00 | E12: Fabricação de alimentos e pratos prontos | G12: 1081-3/02 | H12: Torrefação e moagem de café
A13: 0116-4/01 | B13: Cultivo de amendoim | C13: =MATCH(A13,PRINCIPAL!A:A,0) -> 12 | D13: 1099-6/05 | E13: Fabricação de produtos para infusão (chá, mate, etc.) | G13: 1082-1/00 | H13: Fabricação de produtos à base de café
A14: 0116-4/02 | B14: Cultivo de girassol | C14: =MATCH(A14,PRINCIPAL!A:A,0) -> 13 | D14: 3250-7/03 | E14: Fabricação de aparelhos e utensílios para correção de defeitos físicos e aparelhos ortopédicos em geral sob encomenda | G14: 1091-1/01 | H14: Fabricação de produtos de panificação industrial
... A82: 0162-8/99 | B82: Atividades de apoio à pecuária não especificadas anteriormente | C82: =MATCH(A82,PRINCIPAL!A:A,0) -> 81 | D82: 9609-2/05 | E82: Atividades de sauna e banhos | G82: 8640-2/11 | H82: Serviços de radioterapia
A83: 0163-6/00 | B83: Atividades de pós-colheita | C83: =MATCH(A83,PRINCIPAL!A:A,0) -> 82 | G83: 8640-2/12 | H83: Serviços de hemoterapia - inclusive bancos de
A84: 0170-9/00 | B84: Caça e serviços relacionados | C84: =MATCH(A84,PRINCIPAL!A:A,0) -> 83 | H84: sangue
A85: 0210-1/01 | B85: Cultivo de eucalipto | C85: =MATCH(A85,PRINCIPAL!A:A,0) -> 84 | G85: 8640-2/13 | H85: Serviços de litotripsia
A86: 0210-1/02 | B86: Cultivo de acácia-negra | C86: =MATCH(A86,PRINCIPAL!A:A,0) -> 85 | G86: 8640-2/14 | H86: Serviços de bancos de células e tecidos humanos - inclusive Centro de Terapia Celular
A87: 0210-1/03 | B87: Cultivo de pinus | C87: =MATCH(A87,PRINCIPAL!A:A,0) -> 86 | G87: 8640-2/99 | H87: Atividades de serviços de complementação diagnóstica e terapêutica não especificadas anteriormente
A88: 0210-1/04 | B88: Cultivo de teca | C88: =MATCH(A88,PRINCIPAL!A:A,0) -> 87 | G88: 8650-0/07 | H88: Atividades de terapia de nutrição enteral e parenteral
A89: 0210-1/05 | B89: Cultivo de espécies madeireiras, exceto eucalipto, acácia-negra, pinus e teca | C89: =MATCH(A89,PRINCIPAL!A:A,0) -> 88 | G89: 8650-0/99 | H89: Atividades de profissionais da área de saúde não especificadas anteriormente
A90: 0210-1/06 | B90: Cultivo de mudas em viveiros florestais | C90: =MATCH(A90,PRINCIPAL!A:A,0) -> 89 | G90: 8690-9/02 | H90: Atividades de Bancos de Leite Humano - inclusive posto de coleta
A91: 0210-1/07 | B91: Extração de madeira em florestas plantadas | C91: =MATCH(A91,PRINCIPAL!A:A,0) -> 90 | G91: 8690-9/99 | H91: Outras atividades de atenção à saúde humana não especificadas anteriormente
A92: 0210-1/08 | B92: Produção de carvão vegetal - florestas plantadas | C92: =MATCH(A92,PRINCIPAL!A:A,0) -> 91 | G92: 8711-5/01 | H92: Clínicas e residências geriátricas
A93: 0210-1/09 | B93: Produção de casca de acácia-negra - florestas plantadas | C93: =MATCH(A93,PRINCIPAL!A:A,0) -> 92 | G93: 8711-5/02 | H93: Instituições de longa permanência para idosos
A94: 0210-1/99 | B94: Produção de produtos não madeireiros não especificados anteriormente em florestas plantadas | C94: =MATCH(A94,PRINCIPAL!A:A,0) -> 93 | G94: 8711-5/05 | H94: Condomínios residenciais para idosos - Incluindo Centros de Atenção Diária e Centro de Convivência de Idosos
A95: 0220-9/01 | B95: Extração de madeira em florestas nativas | C95: =MATCH(A95,PRINCIPAL!A:A,0) -> 94 | G95: 8720-4/01 | H95: Atividades de centros de assistência psicossocial - CAPS AD, I, 1, 2, 3 ou 4
A96: 0220-9/02 | B96: Produção de carvão vegetal - florestas nativas | C96: =MATCH(A96,PRINCIPAL!A:A,0) -> 95 | G96: 8720-4/99 | H96: Atividades de assistência psicossocial e à saúde a portadores de distúrbios psíquicos, deficiência mental e dependência química e grupos similares não especificadas anteriormente - Incluindo Serviços Residenciais Terapêuticos em Saúde Mental, Comunidades Terapêuticas de Saúde e de Interesse da Saúde
... A100: 0220-9/06 | B100: Conservação de florestas nativas | C100: =MATCH(A100,PRINCIPAL!A:A,0) -> 99 | G100: 9609-2/06 | H100: Serviços de tatuagem e colocação de piercing
A101: 0220-9/99 | B101: Coleta de produtos não madeireiros não especificados anteriormente em florestas nativas | C101: =MATCH(A101,PRINCIPAL!A:A,0) -> 100
A102: 0230-6/00 | B102: Atividades de apoio à produção florestal | C102: =MATCH(A102,PRINCIPAL!A:A,0) -> 101
A103: 0311-6/01 | B103: Pesca de peixes em água salgada | C103: =MATCH(A103,PRINCIPAL!A:A,0) -> 102
A104: 0311-6/02 | B104: Pesca de crustáceos e moluscos em água salgada | C104: =MATCH(A104,PRINCIPAL!A:A,0) -> 103
A105: 0311-6/03 | B105: Coleta de outros produtos marinhos | C105: =MATCH(A105,PRINCIPAL!A:A,0) -> 104
A106: 0311-6/04 | B106: Atividades de apoio à pesca em água salgada | C106: =MATCH(A106,PRINCIPAL!A:A,0) -> 105
A107: 0312-4/01 | B107: Pesca de peixes em água doce | C107: =MATCH(A107,PRINCIPAL!A:A,0) -> 106
A108: 0312-4/02 | B108: Pesca de crustáceos e moluscos em água doce | C108: =MATCH(A108,PRINCIPAL!A:A,0) -> 107
A109: 0312-4/03 | B109: Coleta de outros produtos aquáticos de água doce | C109: =MATCH(A109,PRINCIPAL!A:A,0) -> 108
A110: 0312-4/04 | B110: Atividades de apoio à pesca em água doce | C110: =MATCH(A110,PRINCIPAL!A:A,0) -> 109
...

Sheet Lista IMA
A1: CNAE | B1: Descrição da Atividade
A2: 0111-3/02 | B2: Cultivo de milho
A3: 0111-3/03 | B3: Cultivo de trigo
A4: 0111-3/99 | B4: Cultivo de outros cereais não especificados anteriormente
A5: 0112-1/01 | B5: Cultivo de algodão herbáceo
A6: 0112-1/02 | B6: Cultivo de juta
A7: 0112-1/99 | B7: Cultivo de outras fibras de lavoura temporária não especificadas anteriormente
A8: 0113-0/00 | B8: Cultivo de cana-de-açúcar
A9: 0114-8/00 | B9: Cultivo de fumo
A10: 0115-6/00 | B10: Cultivo de soja
A11: 0116-4/01 | B11: Cultivo de amendoim
A12: 0116-4/02 | B12: Cultivo de girassol
... A697: 9900-8/00 | B697: Organismos internacionais e outras instituições extraterritoriais
B699: Lista das Atividades Econômicas dispensadas sumariamente do licenciamento ambiental no Estado de Santa Catarina*
B700: *Esta listagem não substitui o texto da Portaria IMA nº 229, de 4 de novembro de 2019 (publicada no D.O.E. em 6 de novembro de 2019), e Portaria IMA nº 106, de 9 de junho de 2020 (publicada no D.O.E. em 10 de junho de 2020). Se a atividade estiver localizada em algum município habilitado ao licenciamento ambiental (consulte aqui), a Declaração de Atividade Não Constante deve ser solicitada junto ao órgão ambiental do município.

Sheet CNAES 2.3
A1: CNAES | B1: DESCRIÇÃO CNAES 2.3
A2: 0111-3/01 | B2: Cultivo de arroz | C2: =MATCH(A2,PRINCIPAL!A:A,0) -> 2
A3: 0111-3/02 | B3: Cultivo de milho | C3: =MATCH(A3,PRINCIPAL!A:A,0) -> 3
A4: 0111-3/03 | B4: Cultivo de trigo | C4: =MATCH(A4,PRINCIPAL!A:A,0) -> 4
A5: 0111-3/99 | B5: Cultivo de outros cereais não especificados anteriormente | C5: =MATCH(A5,PRINCIPAL!A:A,0) -> 5
A6: 0112-1/01 | B6: Cultivo de algodão herbáceo | C6: =MATCH(A6,PRINCIPAL!A:A,0) -> 6
A7: 0112-1/02 | B7: Cultivo de juta | C7: =MATCH(A7,PRINCIPAL!A:A,0) -> 7
A8: 0112-1/99 | B8: Cultivo de outras fibras de lavoura temporária não especificadas anteriormente | C8: =MATCH(A8,PRINCIPAL!A:A,0) -> 8
A9: 0113-0/00 | B9: Cultivo de cana-de-açúcar | C9: =MATCH(A9,PRINCIPAL!A:A,0) -> 9
A10: 0114-8/00 | B10: Cultivo de fumo | C10: =MATCH(A10,PRINCIPAL!A:A,0) -> 10
A11: 0115-6/00 | B11: Cultivo de soja | C11: =MATCH(A11,PRINCIPAL!A:A,0) -> 11
A12: 0116-4/01 | B12: Cultivo de amendoim | C12: =MATCH(A12,PRINCIPAL!A:A,0) -> 12
A13: 0116-4/02 | B13: Cultivo de girassol | C13: =MATCH(A13,PRINCIPAL!A:A,0) -> 13
... A1332: 9700-5/00 | B1332: Serviços domésticos | C1332: =MATCH(A1332,PRINCIPAL!A:A,0) -> 1337

Sheet Antiga
A1: CNAE | B1: Descrição | C1: Exceções / Restrições / Condicionantes
A2: 1311-1/00 | B2: Preparação e fiação de fibras de algodão. | D2: =MATCH(A2,PRINCIPAL!A:A,0) -> 241
A3: 1312-0/00 | B3: Preparação e fiação de fibras têxteis naturais, exceto algodão. | D3: =MATCH(A3,PRINCIPAL!A:A,0) -> 242
A4: 1340-5/99 | B4: Outros serviços de acabamento em fios, tecidos, artefatos têxteis e peças do vestuário. | D4: =MATCH(A4,PRINCIPAL!A:A,0) -> 251
A5: 1351-1/00 | B5: Fabricação de artefatos têxteis para uso doméstico. | D5: =MATCH(A5,PRINCIPAL!A:A,0) -> 252
A6: 1354-5/00 | B6: Fabricação de tecidos especiais, inclusive artefatos, desde que a área construída do empreendimento não ultrapasse 2.500m² (dois mil e quinhentos metros quadrados). | D6: =MATCH(A6,PRINCIPAL!A:A,0) -> 255
A7: 1359-6/00 | B7: Fabricação de outros produtos têxteis não especificados anteriormente. | D7: =MATCH(A7,PRINCIPAL!A:A,0) -> 256
A8: 1521-1/00 | B8: Fabricação de artigos para viagem, bolsas e semelhantes de qualquer material. | C8: desde que a área construída do empreendimento não ultrapasse 2.500m² (dois mil e quinhentos metros quadrados). | D8: =MATCH(A8,PRINCIPAL!A:A,0) -> 269
A9: 1529-7/00 | B9: Fabricação de artefatos de couro não especificados anteriormente. | D9: =MATCH(A9,PRINCIPAL!A:A,0) -> 270
A10: 1531-9/01 | B10: Fabricação de calçados de couro, desde que a área construída do empreendimento não ultrapasse 2.500m² (dois mil e quinhentos metros quadrados). | D10: =MATCH(A10,PRINCIPAL!A:A,0) -> 271
A11: 2319-2/00 | B11: Fabricação de artigos de vidro. | C11: Exceto destinados para alimentos e bebidas. | D11: =MATCH(A11,PRINCIPAL!A:A,0) -> 367
A12: 2399-1/01 | B12: Decoração, lapidação, gravação, vitrificação e outros trabalhos em cerâmica, louça, vidro e cristal. | D12: =MATCH(A12,PRINCIPAL!A:A,0) -> 384
A13: 3291-4/00 | B13: Fabricação de escovas, pincéis e vassouras. | C13: Exceto escovas de dente. | D13: =MATCH(A13,PRINCIPAL!A:A,0) -> 542
A14: 3299-0/06 | B14: Fabricação de velas, inclusive decorativas, desde que não haja, no exercício da atividade, a fabricação de velas, sebo e/ou estearina utilizadas como cosmético ou saneante. | D14: =MATCH(A14,PRINCIPAL!A:A,0) -> 550
A15: 3312-1/02 | B15: Manutenção e reparação de aparelhos e instrumentos de medida, teste e controle. | D15: =MATCH(A15,PRINCIPAL!A:A,0) -> 553
A16: 3312-1/04 | B16: Manutenção e reparação de equipamentos e instrumentos ópticos. | D16: =MATCH(A16,PRINCIPAL!A:A,0) -> 555
A17: 4520-0/03 | B17: Serviços de manutenção e reparação elétrica de veículos automotores. | D17: =MATCH(A17,PRINCIPAL!A:A,0) -> 670
A18: 4520-0/04 | B18: Serviços de alinhamento e balanceamento de veículos automotores. | D18: =MATCH(A18,PRINCIPAL!A:A,0) -> 671
A19: 4520-0/05 | B19: Serviços de lavagem, lubrificação e polimento de veículos automotores. | D19: =MATCH(A19,PRINCIPAL!A:A,0) -> 672
A20: 4520-0/07 | B20: Serviços de instalação, manutenção e reparação de acessórios para veículos automotores. | D20: =MATCH(A20,PRINCIPAL!A:A,0) -> 674
A21: 4541-2/06 | B21: Comércio a varejo de peças e acessórios para motocicletas e motonetas. | D21: =MATCH(A21,PRINCIPAL!A:A,0) -> 687
A22: 4641-9/01 | B22: Comércio atacadista de tecidos. | D22: =MATCH(A22,PRINCIPAL!A:A,0) -> 743
A23: 4641-9/02 | B23: Comércio atacadista de artigos de cama, mesa e banho. | D23: =MATCH(A23,PRINCIPAL!A:A,0) -> 744
A24: 4641-9/03 | B24: Comércio atacadista de artigos de armarinho. | D24: =MATCH(A24,PRINCIPAL!A:A,0) -> 745
A25: 4642-7/01 | B25: Comércio atacadista de artigos do vestuário e acessórios, exceto profissionais e de segurança. | D25: =MATCH(A25,PRINCIPAL!A:A,0) -> 746
... A39: 4686-9/01 | B39: Comércio atacadista de papel e papelão em bruto. | D39: =MATCH(A39,PRINCIPAL!A:A,0) -> 800
A40: 4686-9/02 | B40: Comércio atacadista de embalagens. | C40: Exceto para alimentos ou bebidas. | D40: =MATCH(A40,PRINCIPAL!A:A,0) -> 801
A41: 4687-7/01 | B41: Comércio atacadista de resíduos de papel e papelão. | D41: =MATCH(A41,PRINCIPAL!A:A,0) -> 802
A42: 4687-7/03 | B42: Comércio atacadista de resíduos e sucatas metálicos. | D42: =MATCH(A42,PRINCIPAL!A:A,0) -> 804
A43: 4689-3/02 | B43: Comércio atacadista de fios e fibras beneficiados. | D43: =MATCH(A43,PRINCIPAL!A:A,0) -> 806
A44: 4692-3/00 | B44: Comércio atacadista de mercadorias em geral, com predominância de insumos agropecuários. | D44: =MATCH(A44,PRINCIPAL!A:A,0) -> 809
A45: 5232-0/00 | B45: Atividades de agenciamento marítimo. | D45: =MATCH(A45,PRINCIPAL!A:A,0) -> 944
A46: 5811-5/00 | B46: Edição de livros. | D46: =MATCH(A46,PRINCIPAL!A:A,0) -> 975
A47: 5812-3/01 | B47: Edição de jornais diários. | D47: =MATCH(A47,PRINCIPAL!A:A,0) -> 976
A48: 5812-3/02 | B48: Edição de jornais não diários. | D48: =MATCH(A48,PRINCIPAL!A:A,0) -> 977
A49: 5813-1/00 | B49: Edição de revistas. | D49: =MATCH(A49,PRINCIPAL!A:A,0) -> 978
A50: 5819-1/00 | B50: Edição de cadastros, listas e outros produtos gráficos. | D50: =MATCH(A50,PRINCIPAL!A:A,0) -> 979
A51: 7120-1/00 | B51: Testes e análises técnicas. | C51: Exceto Laboratórios Analíticos para análise de produtos sujeitos à vigilância sanitária. | D51: =MATCH(A51,PRINCIPAL!A:A,0) -> 1107
A52: 7490-1/03 | B52: Serviços de agronomia e de consultoria às atividades agrícolas e pecuárias. | D52: =MATCH(A52,PRINCIPAL!A:A,0) -> 1128
A53: 7500-1/00 | B53: Atividades veterinárias. | C53: Que NÃO utilizem medicamentos ou equipamentos de saúde humana. | D53: =MATCH(A53,PRINCIPAL!A:A,0) -> 1132
...

Sheet Atividades
B1: MEI | F1: OUTROS
A2: CNAE | B2: OCUPAÇÃO | C2: Restrição que deve constar no objeto social, para a liberação do Alvará de Licença de Atividade | E2: CNAE | F2: DESCRIÇÃO SUBCLASSE CNAE | G2: Restrição que deve constar no objeto social, para a liberação do Alvará de Licença de Atividade
A3: 1412-6/01 | B3: COSTUREIRO(A) DE ROUPAS, EXCETO SOB MEDIDA | C3: EXCLUSIVAMENTE NO CLIENTE / SEM DEPÓSITO DE MATERIAIS E MERCADORIAS | E3: 3321-0/00 | F3: INSTALAÇÃO E MONTAGEM DE APARELHOS E EQUIPAMENTOS DE IRRADIAÇÃO ELETROMÉDICOS E ELETROTERAPÊUTICOS | G3: EXCLUSIVAMENTE NO CLIENTE
A4: 1412-6/02 | B4: COSTUREIRO(A) DE ROUPAS, SOB MEDIDA | C4: EXCLUSIVAMENTE NO CLIENTE / SEM DEPÓSITO DE MATERIAIS E MERCADORIAS | E4: 3321-0/00 | F4: INSTALAÇÃO E MONTAGEM DE EQUIPAMENTOS E INSTRUMENTOS DE MEDIDA, TESTE E CONTROLE | G4: EXCLUSIVAMENTE NO CLIENTE
A5: 3314-7/01 | B5: REPARADOR(A) DE MÁQUINAS MOTRIZES NÃO-ELÉTRICAS | C5: EXCLUSIVAMENTE NO CLIENTE | E5: 3321-0/00 | F5: INSTALAÇÃO E MONTAGEM DE GERADORES, TRANSFORMADORES, MOTORES E OUTROS EQUIPAMENTOS ELÉTRICOS | G5: EXCLUSIVAMENTE NO CLIENTE
A6: 3314-7/06 | B6: REPARADOR(A) DE MÁQUINAS, APARELHOS E EQUIPAMENTOS PARA INSTALAÇÕES TÉRMICAS | C6: EXCLUSIVAMENTE NO CLIENTE | E6: 3321-0/00 | F6: INSTALAÇÃO E MONTAGEM DE MÁQUINAS E EQUIPAMENTOS PARA INDUSTRIA DO PLÁSTICO | G6: EXCLUSIVAMENTE NO CLIENTE
A7: 3314-7/07 | B7: REPARADOR(A) DE MÁQUINAS E APARELHOS DE REFRIGERAÇÃO E VENTILAÇÃO PARA USO INDUSTRIAL E COMERCIAL | C7: EXCLUSIVAMENTE NO CLIENTE | E7: 3321-0/00 | F7: INSTALAÇÃO E MONTAGEM DE MÁQUINAS E EQUIPAMENTOS PARA INDUSTRIA TÊXTIL, DO VESTUÁRIO, COURO E CALÇADOS | G7: EXCLUSIVAMENTE NO CLIENTE
A8: 3314-7/10 | B8: REPARADOR(A) DE MÁQUINAS PARA BARES E LANCHONETES | C8: EXCLUSIVAMENTE NO CLIENTE | E8: 3321-0/00 | F8: INSTALAÇÃO E MONTAGEM DE MÁQUINAS E EQUIPAMENTOS PARA TERRAPLENAGEM, PAVIMENTAÇÃO E CONSTRUÇÃO | G8: EXCLUSIVAMENTE NO CLIENTE
A9: 3314-7/11 | B9: REPARADOR(A) DE MÁQUINAS E EQUIPAMENTOS PARA AGRICULTURA E PECUÁRIA | C9: EXCLUSIVAMENTE NO CLIENTE | E9: 3321-0/00 | F9: INSTALAÇÃO E MONTAGEM DE MÁQUINAS E EQUIPAMENTOS PARA USO AGRÍCOLA | G9: EXCLUSIVAMENTE NO CLIENTE
A10: 3314-7/12 | B10: REPARADOR(A) DE TRATORES AGRÍCOLAS | C10: EXCLUSIVAMENTE NO CLIENTE | E10: 3321-0/00 | F10: INSTALAÇÃO E MONTAGEM DE MÁQUINAS E EQUIPAMENTOS PARA USO GERAL | G10: EXCLUSIVAMENTE NO CLIENTE
A11: 3314-7/19 | B11: REPARADOR(A) DE MÁQUINAS E EQUIPAMENTOS PARA AS INDÚSTRIAS DE ALIMENTOS, BEBIDAS E FUMO | C11: EXCLUSIVAMENTE NO CLIENTE | E11: 3321-0/00 | F11: INSTALAÇÃO E MONTAGEM DE MÁQUINAS E EQUIPAMENTOS PARA USO NA EXTRAÇÃO MINERAL, | G11: EXCLUSIVAMENTE NO CLIENTE
A12: 3314-7/20 | B12: REPARADOR(A) DE MÁQUINAS E EQUIPAMENTOS PARA A INDÚSTRIA TÊXTIL, DO VESTUÁRIO, DO COURO E CALÇADOS | C12: EXCLUSIVAMENTE NO CLIENTE | E12: 3321-0/00 | F12: INSTALAÇÃO E MONTAGEM DE MÁQUINAS E EQUIPAMENTOS PARA USOS INDUSTRIAIS ESPECÍFICO | G12: EXCLUSIVAMENTE NO CLIENTE
A13: 3314-7/99 | B13: REPARADOR(A) DE MÁQUINAS E APARELHOS PARA A INDÚSTRIA GRÁFICA | C13: EXCLUSIVAMENTE NO CLIENTE | E13: 3321-0/00 | F13: INSTALAÇÃO E MONTAGEM DE MÁQUINAS-FERRAMENTA | G13: EXCLUSIVAMENTE NO CLIENTE
... A23: 4322-3/01 | B23: BOMBEIRO(A) HIDRÁULICO | C23: EXCLUSIVAMENTE NO CLIENTE | E23: 3329-5/01 | F23: MONTAGEM DE MOVEIS DE QUALQUER MATERIAL PARA CONSUMIDOR FINAL, NÃO ASSOCIADA AO COMÉRCIO, QUANDO EXECUTADA POR UNIDADE ESPECIALIZADA | G23: EXCLUSIVAMENTE NO CLIENTE
A24: 4322-3/01 | B24: ENCANADOR | C24: EXCLUSIVAMENTE NO CLIENTE | E24: 4110-7/00 | F24: INCORPORAÇÃO DE IMÓVEIS POR CONTA PRÓPRIA
A25: 4322-3/02 | B25: INSTALADOR(A) E REPARADOR(A) DE SISTEMAS CENTRAIS DE AR CONDICIONADO, DE VENTILAÇÃO E REFRIGERAÇÃO | C25: EXCLUSIVAMENTE NO CLIENTE | E25: 4110-7/00 | F25: INCORPORAÇÃO DE IMÓVEIS PRÓPRIOS
A26: 4322-3/03 | B26: INSTALADOR(A) DE SISTEMA DE PREVENÇÃO CONTRA INCÊNDIO | C26: EXCLUSIVAMENTE NO CLIENTE | E26: 4321-5/00 | F26: CONSTRUÇÃO E MANUTENÇÃO DE INSTALAÇÕES PARA CENTRO DE PROCESSAMENTO DE DADOS | G26: EXCLUSIVAMENTE NO CLIENTE
A27: 4329-1/01 | B27: INSTALADOR(A) DE PAINÉIS PUBLICITÁRIOS | C27: EXCLUSIVAMENTE NO CLIENTE / SEM DEPÓSITO DE MATERIAIS E MERCADORIAS | E27: 4321-5/00 | F27: CPD, CONSTRUÇÃO E MANUTENÇÃO DE INSTALAÇÕES | G27: EXCLUSIVAMENTE NO CLIENTE
A28: 4329-1/02 | B28: INSTALADOR(A) DE EQUIPAMENTOS PARA ORIENTAÇÃO À NAVEGAÇÃO MARÍTIMA, FLUVIAL E LACUSTRE | C28: EXCLUSIVAMENTE NO CLIENTE | E28: 4321-5/00 | F28: INSTALAÇÃO DE ALARME CONTRA ROUBO EM EDIFICAÇÕES | G28: EXCLUSIVAMENTE NO CLIENTE
A29: 4329-1/03 | B29: INSTALADOR(A) E REPARADOR(A) DE ELEVADORES, ESCADAS E ESTEIRAS ROLANTES | C29: EXCLUSIVAMENTE NO CLIENTE | E29: 4321-5/00 | F29: INSTALAÇÃO DE ANTENAS COLETIVAS E PARABÓLICAS | G29: EXCLUSIVAMENTE NO CLIENTE
A30: 4329-1/05 | B30: INSTALADOR(A) DE ISOLANTES ACÚSTICOS E DE VIBRAÇÃO | C30: EXCLUSIVAMENTE NO CLIENTE | E30: 4321-5/00 | F30: INSTALAÇÃO DE ANTENAS DE TELEVISÃO | G30: EXCLUSIVAMENTE NO CLIENTE
A31: 4329-1/05 | B31: INSTALADOR(A) DE ISOLANTES TÉRMICOS | C31: EXCLUSIVAMENTE NO CLIENTE | E31: 4321-5/00 | F31: INSTALAÇÃO DE CABEAÇÃO LÓGICA | G31: EXCLUSIVAMENTE NO CLIENTE
A32: 4330-4/02 | B32: CARPINTEIRO(A) INSTALADOR(A) | C32: EXCLUSIVAMENTE NO CLIENTE | E32: 4321-5/00 | F32: INSTALAÇÃO DE CABOS PARA INSTALAÇÕES DE COMUNICAÇÃO E INFORMÁTICA EM EDIFICAÇÕES | G32: EXCLUSIVAMENTE NO CLIENTE
A33: 4330-4/03 | B33: GESSEIRO(A) | C33: EXCLUSIVAMENTE NO CLIENTE / SEM DEPÓSITO DE MATERIAL | E33: 4321-5/00 | F33: INSTALAÇÃO DE CABOS PARA INSTALAÇÕES TELEFÔNICAS EM EDIFICAÇÕES | G33: EXCLUSIVAMENTE NO CLIENTE
A34: 4330-4/04 | B34: PINTOR(A) DE PAREDE | C34: EXCLUSIVAMENTE NO CLIENTE / SEM DEPÓSITO DE MATERIAL | E34: 4321-5/00 | F34: INSTALAÇÃO DE CABOS PARA TELEVISÃO EM EDIFICAÇÕES | G34: EXCLUSIVAMENTE NO CLIENTE
A35: 4330-4/05 | B35: AZULEJISTA | C35: EXCLUSIVAMENTE NO CLIENTE / SEM DEPÓSITO DE MATERIAL | E35: 4321-5/00 | F35: INSTALAÇÃO DE CAIXAS DE ENTRADA DE ENERGIA EM EDIFICAÇÕES | G35: EXCLUSIVAMENTE NO CLIENTE
A36: 4330-4/05 | B36: CALAFETADOR(A) | C36: EXCLUSIVAMENTE NO CLIENTE / SEM DEPÓSITO DE MATERIAL | E36: 4321-5/00 | F36: INSTALAÇÃO DE EQUIPAMENTOS DE INTERCOMUNICAÇÃO EM EDIFICAÇÕES | G36: EXCLUSIVAMENTE NO CLIENTE
A37: 4330-4/05 | B37: COLOCADOR(A) DE REVESTIMENTOS | C37: EXCLUSIVAMENTE NO CLIENTE / SEM DEPÓSITO DE MATERIAL | E37: 4321-5/00 | F37: INSTALAÇÃO DE PADRÃO DE ENERGIA (CAIXAS, QUADROS, PAINÉIS OU CUBÍCULOS) | G37: EXCLUSIVAMENTE NO CLIENTE
... A45: 4772-5/00 | B45: COMERCIANTE DE COSMÉTICOS E ARTIGOS DE PERFUMARIA | C45: EXCLUSIVAMENTE NO CLIENTE / SEM ESTOQUE | E45: 4321-5/00 | F45: INSTALAÇÃO DE SISTEMAS DE ELETRICIDADE (CABOS DE QUALQUER TENSÃO, FIAÇÃO, MATERIAIS ELÉTRICOS) | G45: EXCLUSIVAMENTE NO CLIENTE
A46: 4923-0/01 | B46: MOTOTAXISTA | E46: 4321-5/00 | F46: INSTALAÇÃO DE SISTEMAS ELÉTRICOS EM EDIFICAÇÕES | G46: EXCLUSIVAMENTE NO CLIENTE
A47: 4924-8/00 | B47: TRANSPORTADOR(A) ESCOLAR INDEPENDENTE | C47: NÃO UTILIZAR VIA PÚBLICA COMO LOCAL DE GUARDA DO VEÍCULO QUANDO O MESMO NÃO ESTIVER EM SERVIÇO. | E47: 4321-5/00 | F47: INSTALAÇÃO E MANUTENÇÃO DE AUTOMAÇÃO PREDIAL | G47: EXCLUSIVAMENTE NO CLIENTE
A48: 4929-9/01 | B48: TRANSPORTADOR(A) MUNICIPAL DE PASSAGEIROS SOB FRETE INDEPENDENTE | C48: NÃO UTILIZAR VIA PÚBLICA COMO LOCAL DE GUARDA DO VEÍCULO QUANDO O MESMO NÃO ESTIVER EM SERVIÇO. | E48: 4321-5/00 | F48: INSTALAÇÃO E MANUTENÇÃO DE CABOS ELÉTRICOS EM EDIFICAÇÕES | G48: EXCLUSIVAMENTE NO CLIENTE
A49: 4929-9/02 | B49: TRANSPORTADOR(A) INTERMUNICIPAL DE PASSAGEIROS SOB FRETE EM REGIÃO METROPOLITANA INDEPENDENTE | C49: NÃO UTILIZAR VIA PÚBLICA COMO LOCAL DE GUARDA DO VEÍCULO QUANDO O MESMO NÃO ESTIVER EM SERVIÇO | E49: 4321-5/00 | F49: MANUTENÇÃO DE INSTALAÇÕES PARA ANTENAS COLETIVAS E PARABÓLICAS | G49: EXCLUSIVAMENTE NO CLIENTE
A50: 4929-9/03 | B50: ORGANIZADOR(A) DE EXCURSÕES EM VEÍCULO PRÓPRIO, MUNICIPAL | E50: 4321-5/00 | F50: MANUTENÇÃO DE INSTALAÇÕES PARA PÁRA-RAIOS | G50: EXCLUSIVAMENTE NO CLIENTE
A51: 4929-9/03 | B51: ORGANIZADOR(A) DE EXCURSÕES EM VEÍCULO PRÓPRIO, MUNICIPAL INDEPENDENTE | C51: NÃO UTILIZAR VIA PÚBLICA COMO LOCAL DE GUARDA DO VEÍCULO QUANDO O MESMO NÃO ESTIVER EM SERVIÇO | E51: 4321-5/00 | F51: MANUTENÇÃO DE INSTALAÇÕES PARA PORTÃO ELETRÔNICO | G51: EXCLUSIVAMENTE NO CLIENTE
A52: 5212-5/00 | B52: CARREGADOR (VEÍCULOS DE TRANSPORTES TERRESTRES) | C52: EXCLUSIVAMENTE NO CLIENTE | E52: 4321-5/00 | F52: MANUTENÇÃO DE INSTALAÇÕES PARA SISTEMA DE ALARMES CONTRA ROUBOS EM EDIFICAÇÕES | G52: EXCLUSIVAMENTE NO CLIENTE
A53: 5229-0/02 | B53: GUINCHEIRO (REBOQUE DE VEÍCULOS) | C53: EXCLUSIVAMENTE NO CLIENTE / SEM DEPÓSITO PARA VEÍCULOS | E53: 4321-5/00 | F53: MANUTENÇÃO DE PÁRA-RAIOS | G53: EXCLUSIVAMENTE NO CLIENTE
A54: 5320-2/01 | B54: ENTREGADOR DE MALOTES | C54: EXCLUSIVAMENTE NO CLIENTE / SEM DEPÓSITO DE MATERIAIS | E54: 4321-5/00 | F54: MANUTENÇÃO DE PORTÃO ELETRÔNICO | G54: EXCLUSIVAMENTE NO CLIENTE
A55: 5320-2/02 | B55: BIKEBOY (CICLISTA MENSAGEIRO) | C55: EXCLUSIVAMENTE NO CLIENTE / SEM DEPÓSITO DE MATERIAIS / EXCETO MEDICAMENTOS | E55: 4321-5/00 | F55: MANUTENÇÃO DE SISTEMAS DE ALARMES CONTRA ROUBO EM EDIFICAÇÕES | G55: EXCLUSIVAMENTE NO CLIENTE
A56: 5320-2/02 | B56: MOTOBOY | E56: 4321-5/00 | F56: OBRAS DE INSTALAÇÃO, MANUTENÇÃO E REPARAÇÃO CABOS PARA INSTALAÇÕES TELEFÔNICAS, INFORMÁTICAS E COMUNICAÇÕES EM EDIFICAÇÕES DE QUALQUER TIPO | G56: EXCLUSIVAMENTE NO CLIENTE
...

Sheet Atividades 2
A1: OUTROS
A2: CNAE | B2: DESCRIÇÃO SUBCLASSE CNAE | C2: Restrição que deve constar no objeto social, para a liberação do Alvará de Licença de Atividade
A3: 3321-0/00 | B3: INSTALAÇÃO E MONTAGEM DE APARELHOS E EQUIPAMENTOS DE IRRADIAÇÃO ELETROMÉDICOS E ELETROTERAPÊUTICOS | C3: EXCLUSIVAMENTE NO CLIENTE
A4: 3321-0/00 | B4: INSTALAÇÃO E MONTAGEM DE EQUIPAMENTOS E INSTRU- MENTOS DE MEDIDA, TESTE E CONTROLE | C4: EXCLUSIVAMENTE NO CLIENTE
A5: 3321-0/00 | B5: INSTALAÇÃO E MONTAGEM DE GERADORES, TRANSFORMADO- RES, MOTORES E OUTROS EQUIPAMENTOS ELÉTRICOS | C5: EXCLUSIVAMENTE NO CLIENTE
A6: 3321-0/00 | B6: INSTALAÇÃO E MONTAGEM DE MÁQUINAS E EQUIPAMENTOS PARA INDUSTRIA DO PLÁSTICO | C6: EXCLUSIVAMENTE NO CLIENTE
A7: 3321-0/00 | B7: INSTALAÇÃO E MONTAGEM DE MÁQUINAS E EQUIPAMENTOS PARA INDUSTRIA TÊXTIL, DO VESTUÁRIO, COURO E CALÇADOS | C7: EXCLUSIVAMENTE NO CLIENTE
A8: 3321-0/00 | B8: INSTALAÇÃO E MONTAGEM DE MÁQUINAS E EQUIPAMENTOS PARA TERRAPLENAGEM, PAVIMENTAÇÃO E CONSTRUÇÃO | C8: EXCLUSIVAMENTE NO CLIENTE
A9: 3321-0/00 | B9: INSTALAÇÃO E MONTAGEM DE MÁQUINAS E EQUIPAMENTOS PARA USO AGRÍCOLA | C9: EXCLUSIVAMENTE NO CLIENTE
A10: 3321-0/00 | B10: INSTALAÇÃO E MONTAGEM DE MÁQUINAS E EQUIPAMENTOS PARA USO GERAL | C10: EXCLUSIVAMENTE NO CLIENTE
A11: 3321-0/00 | B11: INSTALAÇÃO E MONTAGEM DE MÁQUINAS E EQUIPAMENTOS PARA USO NA EXTRAÇÃO MINERAL, | C11: EXCLUSIVAMENTE NO CLIENTE
A12: 3321-0/00 | B12: INSTALAÇÃO E MONTAGEM DE MÁQUINAS E EQUIPAMENTOS PARA USOS INDUSTRIAIS ESPECÍFICO | C12: EXCLUSIVAMENTE NO CLIENTE
A13: 3321-0/00 | B13: INSTALAÇÃO E MONTAGEM DE MÁQUINAS-FERRAMENTA | C13: EXCLUSIVAMENTE NO CLIENTE
... A23: 3329-5/01 | B23: MONTAGEM DE MOVEIS DE QUALQUER MATERIAL PARA CON- SUMIDOR FINAL, NÃO ASSOCIADA AO COMÉRCIO, QUANDO EXECUTADA POR UNIDADE ESPECIALIZADA | C23: EXCLUSIVAMENTE NO CLIENTE
A24: 4110-7/00 | B24: INCORPORAÇÃO DE IMÓVEIS POR CONTA PRÓPRIA
A25: 4110-7/00 | B25: INCORPORAÇÃO DE IMÓVEIS PRÓPRIOS
A26: 4321-5/00 | B26: CONSTRUÇÃO E MANUTENÇÃO DE INSTALAÇÕES PARA CEN- TRO DE PROCESSAMENTO DE DADOS | C26: EXCLUSIVAMENTE NO CLIENTE
A27: 4321-5/00 | B27: CPD, CONSTRUÇÃO E MANUTENÇÃO DE INSTALAÇÕES | C27: EXCLUSIVAMENTE NO CLIENTE
A28: 4321-5/00 | B28: INSTALAÇÃO DE ALARME CONTRA ROUBO EM EDIFICAÇÕES | C28: EXCLUSIVAMENTE NO CLIENTE
A29: 4321-5/00 | B29: INSTALAÇÃO DE ANTENAS COLETIVAS E PARABÓLICAS | C29: EXCLUSIVAMENTE NO CLIENTE
A30: 4321-5/00 | B30: INSTALAÇÃO DE ANTENAS DE TELEVISÃO | C30: EXCLUSIVAMENTE NO CLIENTE
A31: 4321-5/00 | B31: INSTALAÇÃO DE CABEAÇÃO LÓGICA | C31: EXCLUSIVAMENTE NO CLIENTE
A32: 4321-5/00 | B32: INSTALAÇÃO DE CABOS PARA INSTALAÇÕES DE COMUNICAÇÃO E INFORMÁTICA EM EDIFICAÇÕES | C32: EXCLUSIVAMENTE NO CLIENTE
A33: 4321-5/00 | B33: INSTALAÇÃO DE CABOS PARA INSTALAÇÕES TELEFÔNICAS EM EDIFICAÇÕES | C33: EXCLUSIVAMENTE NO CLIENTE
A34: 4321-5/00 | B34: INSTALAÇÃO DE CABOS PARA TELEVISÃO EM EDIFICAÇÕES | C34: EXCLUSIVAMENTE NO CLIENTE
A35: 4321-5/00 | B35: INSTALAÇÃO DE CAIXAS DE ENTRADA DE ENERGIA EM EDIFICA- ÇÕES | C35: EXCLUSIVAMENTE NO CLIENTE
A36: 4321-5/00 | B36: INSTALAÇÃO DE EQUIPAMENTOS DE INTERCOMUNICAÇÃO EM EDIFICAÇÕES | C36: EXCLUSIVAMENTE NO CLIENTE
A37: 4321-5/00 | B37: INSTALAÇÃO DE PADRÃO DE ENERGIA (CAIXAS, QUADROS, PAI- NÉIS OU CUBÍCULOS) | C37: EXCLUSIVAMENTE NO CLIENTE
... A459: 4619-2/00 | B459: REPRESENTAÇÃO COMERCIAL E AGENTE DO COMÉRCIO DE PRODUTOS DIVERSOS | C459: SEM DEPÓSITO DE MERCADORIAS
A460: 4929-9/03 | B460: ORGANIZAÇÃO DE EXCURSÕES EM VEÍCULOS RODOVIÁRIOS PRÓPRIOS, MUNICIPAL
A461: 5212-5/00 | B461: SERVIÇOS DE CARGA E DESCARGA | C461: EXCLUSIVAMENTE NO CLIENTE
A462: 5212-5/00 | B462: SERVIÇOS DE CARREGAMENTO E DESCARREGAMENTO DE BA- GAGENS | C462: EXCLUSIVAMENTE NO CLIENTE
A463: 5212-5/00 | B463: SERVIÇOS DE MANUSEIO DE BAGAGENS | C463: EXCLUSIVAMENTE NO CLIENTE
A464: 5212-5/00 | B464: SERVIÇOS DE PATIAMENTO DE CARROS | C464: EXCLUSIVAMENTE NO CLIENTE
A465: 5250-8/01 | B465: ASSESSORIA EM IMPORTAÇÃO E EXPORTAÇÃO DE CARGAS | C465: EXCLUSIVAMENTE NO CLIENTE / EXERCIDAS PELA INTERNET
A466: 5250-8/01 | B466: SERVIÇOS DE ASSESSORIA ADUANEIRA | C466: EXCLUSIVAMENTE NO CLIENTE / EXERCIDAS PELA INTERNET
A467: 5250-8/01 | B467: SERVIÇOS DE COMISSARIA DE DESPACHOS | C467: EXCLUSIVAMENTE NO CLIENTE / EXERCIDAS PELA INTERNET
A468: 5250-8/01 | B468: SERVIÇOS DE DESEMBARAÇO ADUANEIRO | C468: EXCLUSIVAMENTE NO CLIENTE / EXERCIDAS PELA INTERNET
A469: 5250-8/01 | B469: SERVIÇOS DE REGULARIZAÇÃO DE DOCUMENTOS SOBRE EN- TRADA E SAÍDA DE MERCADORIAS | C469: EXCLUSIVAMENTE NO CLIENTE / EXERCIDAS PELA INTERNET
A470: 5250-8/01 | B470: SERVIÇOS DE REGULARIZAÇÃO DE IMPOSTOS SOBRE MERCA- DORIAS | C470: EXCLUSIVAMENTE NO CLIENTE / EXERCIDAS PELA INTERNET
...

Sheet Página2
